Workbook

Sheet RSI_Validation
A1: RSI(14) Manual Validation — EUR/USD
A4: Row | B4: DateTime | C4: Close | D4: Change | E4: Gain | F4: Loss | G4: Avg Gain (EWM) | H4: Avg Loss (EWM) | I4: RSI (Excel) | J4: RSI (Notebook) | K4: Match?
A5: 0 | B5: 2023-01-01 00:00:00 | C5: 1.08054 | E5: 0 | F5: 0 | G5: =E5 -> 0 | H5: =F5 -> 0 | I5: =IFERROR(100-(100/(1+G5/H5)),100) -> 100 | J5: n/a (MACD warm-up) | K5: —
A6: 1 | B6: 2023-01-01 01:00:00 | C6: 1.08028 | D6: =C6-C5 -> -0.00026 | E6: =IF(D6>0,D6,0) -> 0 | F6: =IF(D6<0,-D6,0) -> 0.00026 | G6: =(1/14)*E6+(13/14)*G5 -> 0 | H6: =(1/14)*F6+(13/14)*H5 -> 1.8571429e-05 | I6: =IFERROR(100-(100/(1+G6/H6)),100) -> 0 | J6: n/a (MACD warm-up) | K6: —
A7: 2 | B7: 2023-01-01 02:00:00 | C7: 1.08054 | D7: =C7-C6 -> 0.00026 | E7: =IF(D7>0,D7,0) -> 0.00026 | F7: =IF(D7<0,-D7,0) -> 0 | G7: =(1/14)*E7+(13/14)*G6 -> 1.8571429e-05 | H7: =(1/14)*F7+(13/14)*H6 -> 1.7244898e-05 | I7: =IFERROR(100-(100/(1+G7/H7)),100) -> 51.851852 | J7: n/a (MACD warm-up) | K7: —
A8: 3 | B8: 2023-01-01 03:00:00 | C8: 1.08088 | D8: =C8-C7 -> 0.00034 | E8: =IF(D8>0,D8,0) -> 0.00034 | F8: =IF(D8<0,-D8,0) -> 0 | G8: =(1/14)*E8+(13/14)*G7 -> 4.1530612e-05 | H8: =(1/14)*F8+(13/14)*H7 -> 1.601312e-05 | I8: =IFERROR(100-(100/(1+G8/H8)),100) -> 72.172261 | J8: n/a (MACD warm-up) | K8: —
A9: 4 | B9: 2023-01-01 04:00:00 | C9: 1.0803 | D9: =C9-C8 -> -0.00058 | E9: =IF(D9>0,D9,0) -> 0 | F9: =IF(D9<0,-D9,0) -> 0.00058 | G9: =(1/14)*E9+(13/14)*G8 -> 3.856414e-05 | H9: =(1/14)*F9+(13/14)*H8 -> 5.6297897e-05 | I9: =IFERROR(100-(100/(1+G9/H9)),100) -> 40.652869 | J9: n/a (MACD warm-up) | K9: —
A10: 5 | B10: 2023-01-01 05:00:00 | C10: 1.07998 | D10: =C10-C9 -> -0.00032 | E10: =IF(D10>0,D10,0) -> 0 | F10: =IF(D10<0,-D10,0) -> 0.00032 | G10: =(1/14)*E10+(13/14)*G9 -> 3.5809559e-05 | H10: =(1/14)*F10+(13/14)*H9 -> 7.5133761e-05 | I10: =IFERROR(100-(100/(1+G10/H10)),100) -> 32.277345 | J10: n/a (MACD warm-up) | K10: —
A11: 6 | B11: 2023-01-01 06:00:00 | C11: 1.08087 | D11: =C11-C10 -> 0.00089 | E11: =IF(D11>0,D11,0) -> 0.00089 | F11: =IF(D11<0,-D11,0) -> 0 | G11: =(1/14)*E11+(13/14)*G10 -> 9.6823161e-05 | H11: =(1/14)*F11+(13/14)*H10 -> 6.9767064e-05 | I11: =IFERROR(100-(100/(1+G11/H11)),100) -> 58.120554 | J11: n/a (MACD warm-up) | K11: —
A12: 7 | B12: 2023-01-01 07:00:00 | C12: 1.08108 | D12: =C12-C11 -> 0.00021 | E12: =IF(D12>0,D12,0) -> 0.00021 | F12: =IF(D12<0,-D12,0) -> 0 | G12: =(1/14)*E12+(13/14)*G11 -> 0.00010490722 | H12: =(1/14)*F12+(13/14)*H11 -> 6.4783702e-05 | I12: =IFERROR(100-(100/(1+G12/H12)),100) -> 61.82253 | J12: n/a (MACD warm-up) | K12: —
A13: 8 | B13: 2023-01-01 08:00:00 | C13: 1.08058 | D13: =C13-C12 -> -0.0005 | E13: =IF(D13>0,D13,0) -> 0 | F13: =IF(D13<0,-D13,0) -> 0.0005 | G13: =(1/14)*E13+(13/14)*G12 -> 9.7413848e-05 | H13: =(1/14)*F13+(13/14)*H12 -> 9.5870581e-05 | I13: =IFERROR(100-(100/(1+G13/H13)),100) -> 50.399222 | J13: n/a (MACD warm-up) | K13: —
A14: 9 | B14: 2023-01-01 09:00:00 | C14: 1.08017 | D14: =C14-C13 -> -0.00041 | E14: =IF(D14>0,D14,0) -> 0 | F14: =IF(D14<0,-D14,0) -> 0.00041 | G14: =(1/14)*E14+(13/14)*G13 -> 9.0455716e-05 | H14: =(1/14)*F14+(13/14)*H13 -> 0.0001183084 | I14: =IFERROR(100-(100/(1+G14/H14)),100) -> 43.32915 | J14: n/a (MACD warm-up) | K14: —
A15: 10 | B15: 2023-01-01 10:00:00 | C15: 1.07926 | D15: =C15-C14 -> -0.00091 | E15: =IF(D15>0,D15,0) -> 0 | F15: =IF(D15<0,-D15,0) -> 0.00091 | G15: =(1/14)*E15+(13/14)*G14 -> 8.3994594e-05 | H15: =(1/14)*F15+(13/14)*H14 -> 0.0001748578 | I15: =IFERROR(100-(100/(1+G15/H15)),100) -> 32.448838 | J15: n/a (MACD warm-up) | K15: —
A16: 11 | B16: 2023-01-01 11:00:00 | C16: 1.07906 | D16: =C16-C15 -> -0.0002 | E16: =IF(D16>0,D16,0) -> 0 | F16: =IF(D16<0,-D16,0) -> 0.0002 | G16: =(1/14)*E16+(13/14)*G15 -> 7.799498e-05 | H16: =(1/14)*F16+(13/14)*H15 -> 0.00017665367 | I16: =IFERROR(100-(100/(1+G16/H16)),100) -> 30.628468 | J16: n/a (MACD warm-up) | K16: —
A17: 12 | B17: 2023-01-01 12:00:00 | C17: 1.07945 | D17: =C17-C16 -> 0.00039 | E17: =IF(D17>0,D17,0) -> 0.00039 | F17: =IF(D17<0,-D17,0) -> 0 | G17: =(1/14)*E17+(13/14)*G16 -> 0.00010028105 | H17: =(1/14)*F17+(13/14)*H16 -> 0.00016403555 | I17: =IFERROR(100-(100/(1+G17/H17)),100) -> 37.939748 | J17: n/a (MACD warm-up) | K17: —
... A37: 32 | B37: 2023-01-02 08:00:00 | C37: 1.07443 | D37: =C37-C36 -> -0.00029 | E37: =IF(D37>0,D37,0) -> 0 | F37: =IF(D37<0,-D37,0) -> 0.00029 | G37: =(1/14)*E37+(13/14)*G36 -> 0.00021943891 | H37: =(1/14)*F37+(13/14)*H36 -> 0.0004466769 | I37: =IFERROR(100-(100/(1+G37/H37)),100) -> 32.943057 | J37: n/a (MACD warm-up) | K37: —
A38: 33 | B38: 2023-01-02 09:00:00 | C38: 1.07495 | D38: =C38-C37 -> 0.00052 | E38: =IF(D38>0,D38,0) -> 0.00052 | F38: =IF(D38<0,-D38,0) -> 0 | G38: =(1/14)*E38+(13/14)*G37 -> 0.00024090756 | H38: =(1/14)*F38+(13/14)*H37 -> 0.00041477141 | I38: =IFERROR(100-(100/(1+G38/H38)),100) -> 36.741694 | J38: 36.741694 | K38: =IF(ABS(I38-J38)<0.1,"OK","CHECK") -> OK
A39: 34 | B39: 2023-01-02 10:00:00 | C39: 1.07447 | D39: =C39-C38 -> -0.00048 | E39: =IF(D39>0,D39,0) -> 0 | F39: =IF(D39<0,-D39,0) -> 0.00048 | G39: =(1/14)*E39+(13/14)*G38 -> 0.00022369988 | H39: =(1/14)*F39+(13/14)*H38 -> 0.00041943059 | I39: =IFERROR(100-(100/(1+G39/H39)),100) -> 34.78297 | J39: 34.78297 | K39: =IF(ABS(I39-J39)<0.1,"OK","CHECK") -> OK
A40: 35 | B40: 2023-01-02 11:00:00 | C40: 1.07489 | D40: =C40-C39 -> 0.00042 | E40: =IF(D40>0,D40,0) -> 0.00042 | F40: =IF(D40<0,-D40,0) -> 0 | G40: =(1/14)*E40+(13/14)*G39 -> 0.00023772131 | H40: =(1/14)*F40+(13/14)*H39 -> 0.00038947126 | I40: =IFERROR(100-(100/(1+G40/H40)),100) -> 37.902444 | J40: 37.902444 | K40: =IF(ABS(I40-J40)<0.1,"OK","CHECK") -> OK
A41: 36 | B41: 2023-01-02 12:00:00 | C41: 1.07605 | D41: =C41-C40 -> 0.00116 | E41: =IF(D41>0,D41,0) -> 0.00116 | F41: =IF(D41<0,-D41,0) -> 0 | G41: =(1/14)*E41+(13/14)*G40 -> 0.00030359836 | H41: =(1/14)*F41+(13/14)*H40 -> 0.00036165189 | I41: =IFERROR(100-(100/(1+G41/H41)),100) -> 45.636715 | J41: 45.636715 | K41: =IF(ABS(I41-J41)<0.1,"OK","CHECK") -> OK
A42: 37 | B42: 2023-01-02 13:00:00 | C42: 1.0766 | D42: =C42-C41 -> 0.00055 | E42: =IF(D42>0,D42,0) -> 0.00055 | F42: =IF(D42<0,-D42,0) -> 0 | G42: =(1/14)*E42+(13/14)*G41 -> 0.00032119848 | H42: =(1/14)*F42+(13/14)*H41 -> 0.00033581961 | I42: =IFERROR(100-(100/(1+G42/H42)),100) -> 48.887311 | J42: 48.887311 | K42: =IF(ABS(I42-J42)<0.1,"OK","CHECK") -> OK
A43: 38 | B43: 2023-01-02 14:00:00 | C43: 1.07763 | D43: =C43-C42 -> 0.00103 | E43: =IF(D43>0,D43,0) -> 0.00103 | F43: =IF(D43<0,-D43,0) -> 0 | G43: =(1/14)*E43+(13/14)*G42 -> 0.00037182716 | H43: =(1/14)*F43+(13/14)*H42 -> 0.0003118325 | I43: =IFERROR(100-(100/(1+G43/H43)),100) -> 54.387758 | J43: 54.387758 | K43: =IF(ABS(I43-J43)<0.1,"OK","CHECK") -> OK
A44: 39 | B44: 2023-01-02 15:00:00 | C44: 1.07737 | D44: =C44-C43 -> -0.00026 | E44: =IF(D44>0,D44,0) -> 0 | F44: =IF(D44<0,-D44,0) -> 0.00026 | G44: =(1/14)*E44+(13/14)*G43 -> 0.00034526808 | H44: =(1/14)*F44+(13/14)*H43 -> 0.00030813017 | I44: =IFERROR(100-(100/(1+G44/H44)),100) -> 52.841904 | J44: 52.841904 | K44: =IF(ABS(I44-J44)<0.1,"OK","CHECK") -> OK
A45: 40 | B45: 2023-01-02 16:00:00 | C45: 1.07687 | D45: =C45-C44 -> -0.0005 | E45: =IF(D45>0,D45,0) -> 0 | F45: =IF(D45<0,-D45,0) -> 0.0005 | G45: =(1/14)*E45+(13/14)*G44 -> 0.00032060607 | H45: =(1/14)*F45+(13/14)*H44 -> 0.00032183516 | I45: =IFERROR(100-(100/(1+G45/H45)),100) -> 49.904342 | J45: 49.904342 | K45: =IF(ABS(I45-J45)<0.1,"OK","CHECK") -> OK
A46: 41 | B46: 2023-01-02 17:00:00 | C46: 1.0776 | D46: =C46-C45 -> 0.00073 | E46: =IF(D46>0,D46,0) -> 0.00073 | F46: =IF(D46<0,-D46,0) -> 0 | G46: =(1/14)*E46+(13/14)*G45 -> 0.00034984849 | H46: =(1/14)*F46+(13/14)*H45 -> 0.00029884694 | I46: =IFERROR(100-(100/(1+G46/H46)),100) -> 53.931087 | J46: 53.931087 | K46: =IF(ABS(I46-J46)<0.1,"OK","CHECK") -> OK
A47: 42 | B47: 2023-01-02 18:00:00 | C47: 1.07542 | D47: =C47-C46 -> -0.00218 | E47: =IF(D47>0,D47,0) -> 0 | F47: =IF(D47<0,-D47,0) -> 0.00218 | G47: =(1/14)*E47+(13/14)*G46 -> 0.00032485932 | H47: =(1/14)*F47+(13/14)*H46 -> 0.00043321501 | I47: =IFERROR(100-(100/(1+G47/H47)),100) -> 42.853227 | J47: 42.853227 | K47: =IF(ABS(I47-J47)<0.1,"OK","CHECK") -> OK
A48: 43 | B48: 2023-01-02 19:00:00 | C48: 1.07529 | D48: =C48-C47 -> -0.00013 | E48: =IF(D48>0,D48,0) -> 0 | F48: =IF(D48<0,-D48,0) -> 0.00013 | G48: =(1/14)*E48+(13/14)*G47 -> 0.00030165508 | H48: =(1/14)*F48+(13/14)*H47 -> 0.0004115568 | I48: =IFERROR(100-(100/(1+G48/H48)),100) -> 42.295297 | J48: 42.295297 | K48: =IF(ABS(I48-J48)<0.1,"OK","CHECK") -> OK
A49: 44 | B49: 2023-01-02 20:00:00 | C49: 1.07719 | D49: =C49-C48 -> 0.0019 | E49: =IF(D49>0,D49,0) -> 0.0019 | F49: =IF(D49<0,-D49,0) -> 0 | G49: =(1/14)*E49+(13/14)*G48 -> 0.00041582257 | H49: =(1/14)*F49+(13/14)*H48 -> 0.00038215988 | I49: =IFERROR(100-(100/(1+G49/H49)),100) -> 52.109238 | J49: 52.109238 | K49: =IF(ABS(I49-J49)<0.1,"OK","CHECK") -> OK
... A54: 49 | B54: 2023-01-03 01:00:00 | C54: 1.0718 | D54: =C54-C53 -> -0.00042 | E54: =IF(D54>0,D54,0) -> 0 | F54: =IF(D54<0,-D54,0) -> 0.00042 | G54: =(1/14)*E54+(13/14)*G53 -> 0.00034601416 | H54: =(1/14)*F54+(13/14)*H53 -> 0.00065791037 | I54: =IFERROR(100-(100/(1+G54/H54)),100) -> 34.466153 | J54: 34.466153 | K54: =IF(ABS(I54-J54)<0.1,"OK","CHECK") -> OK

Sheet Trade_Validation
A1: Trade Log Validation — Win Rate & Profit Factor
A4: TradeID | B4: PairName | C4: StrategyName | D4: SignalType | E4: Direction | F4: EntryPrice | G4: ExitPrice | H4: PnL | I4: IsWin (1/0) | J4: Running Wins | K4: Running Win Rate
A5: 1 | B5: USD/JPY | C5: MACD_Trend | D5: BUY | E5: LONG | F5: 154.16999 | G5: 154.17229 | H5: 2300 | I5: =IF(H5>0,1,0) -> 1 | J5: =I5 -> 1 | K5: =J5/(ROW()-5+1) -> 1
A6: 2 | B6: USD/INR | C6: MA_Cross | D6: STRONG_SELL | E6: SHORT | F6: 83.90144 | G6: 83.9007 | H6: 740 | I6: =IF(H6>0,1,0) -> 1 | J6: =J5+I6 -> 2 | K6: =J6/(ROW()-5+1) -> 1
A7: 3 | B7: USD/JPY | C7: RL_PPO | D7: BUY | E7: LONG | F7: 150.56125 | G7: 150.56093 | H7: -320 | I7: =IF(H7>0,1,0) -> 0 | J7: =J6+I7 -> 2 | K7: =J7/(ROW()-5+1) -> 0.66666667
A8: 4 | B8: GBP/USD | C8: ML_RF | D8: SELL | E8: SHORT | F8: 1.23636 | G8: 1.23434 | H8: 202 | I8: =IF(H8>0,1,0) -> 1 | J8: =J7+I8 -> 3 | K8: =J8/(ROW()-5+1) -> 0.75
A9: 5 | B9: AUD/USD | C9: RL_PPO | D9: BUY | E9: LONG | F9: 0.6681 | G9: 0.667 | H9: -110 | I9: =IF(H9>0,1,0) -> 0 | J9: =J8+I9 -> 3 | K9: =J9/(ROW()-5+1) -> 0.6
A10: 6 | B10: EUR/USD | C10: Composite | D10: BUY | E10: LONG | F10: 1.10874 | G10: 1.10988 | H10: 114 | I10: =IF(H10>0,1,0) -> 1 | J10: =J9+I10 -> 4 | K10: =J10/(ROW()-5+1) -> 0.66666667
A11: 7 | B11: USD/JPY | C11: MA_Cross | D11: STRONG_SELL | E11: SHORT | F11: 140.74422 | G11: 140.74573 | H11: -1510 | I11: =IF(H11>0,1,0) -> 0 | J11: =J10+I11 -> 4 | K11: =J11/(ROW()-5+1) -> 0.57142857
A12: 8 | B12: AUD/USD | C12: MA_Cross | D12: STRONG_BUY | E12: LONG | F12: 0.68809 | G12: 0.68928 | H12: 119 | I12: =IF(H12>0,1,0) -> 1 | J12: =J11+I12 -> 5 | K12: =J12/(ROW()-5+1) -> 0.625
A13: 9 | B13: GBP/USD | C13: RL_PPO | D13: BUY | E13: LONG | F13: 1.23686 | G13: 1.24044 | H13: 358 | I13: =IF(H13>0,1,0) -> 1 | J13: =J12+I13 -> 6 | K13: =J13/(ROW()-5+1) -> 0.66666667
A14: 10 | B14: USD/JPY | C14: ML_XGB | D14: BUY | E14: LONG | F14: 151.24139 | G14: 151.24213 | H14: 740 | I14: =IF(H14>0,1,0) -> 1 | J14: =J13+I14 -> 7 | K14: =J14/(ROW()-5+1) -> 0.7
A15: 11 | B15: EUR/USD | C15: MACD_Trend | D15: STRONG_BUY | E15: LONG | F15: 1.07416 | G15: 1.07588 | H15: 172 | I15: =IF(H15>0,1,0) -> 1 | J15: =J14+I15 -> 8 | K15: =J15/(ROW()-5+1) -> 0.72727273
A16: 12 | B16: GBP/USD | C16: ML_XGB | D16: STRONG_SELL | E16: SHORT | F16: 1.28785 | G16: 1.28706 | H16: 79 | I16: =IF(H16>0,1,0) -> 1 | J16: =J15+I16 -> 9 | K16: =J16/(ROW()-5+1) -> 0.75
A17: 13 | B17: AUD/USD | C17: ML_XGB | D17: SELL | E17: SHORT | F17: 0.69478 | G17: 0.69626 | H17: -148 | I17: =IF(H17>0,1,0) -> 0 | J17: =J16+I17 -> 9 | K17: =J17/(ROW()-5+1) -> 0.69230769
... A44: 40 | B44: USD/INR | C44: RL_PPO | D44: STRONG_BUY | E44: LONG | F44: 82.72001 | G44: 82.71786 | H44: -2150 | I44: =IF(H44>0,1,0) -> 0 | J44: =J43+I44 -> 26 | K44: =J44/(ROW()-5+1) -> 0.65
A47: Sample Summary
A48: Total Trades (sample) | B48: =COUNT(A5:A44) -> 40
A49: Winning Trades (sample) | B49: =SUM(I5:I44) -> 26
A50: Win Rate (sample) | B50: =B49/B48 -> 0.65
A51: Avg Trade PnL (sample) | B51: =AVERAGE(H5:H44) -> 310.45
A52: Gross Profit (sample) | B52: =SUMIF(H5:H44,">0") -> 22001
A53: Gross Loss (sample) | B53: =SUMIF(H5:H44,"<0") -> -9583
A54: Profit Factor (sample) | B54: =B52/ABS(B53) -> 2.2958364

Sheet Summary_CrossCheck
A1: Cross-Validation Summary — Excel vs Python vs Power BI (DAX)
A4: Metric | B4: Python (full dataset) | C4: Excel (sample, this workbook) | D4: Power BI / DAX | E4: Match?
A5: Win Rate | B5: 0.56 | C5: =Trade_Validation!B50 -> 0.65 | D5: 0.56
A6: Average Trade PnL | B6: 12.77 | C6: =Trade_Validation!B51 -> 310.45
A7: Profit Factor | B7: 1.028 | C7: =Trade_Validation!B54 -> 2.2958364 | D7: 1.03
A8: Sharpe Ratio | B8: 0.146 | D8: 0.12
A9: RSI(14) — sample row (idx 40) | B9: =RSI_Validation!J44 -> 52.841904 | C9: =RSI_Validation!I44 -> 52.841904 | E9: =IF(ABS(B9-C9)<0.1,"OK","CHECK") -> OK

Sheet MultiPair_Validation
A1: Multi-Pair Trade Validation — EUR/USD, GBP/USD, USD/JPY
A4: EUR/USD (33 trades)
A5: TradeID | B5: StrategyName | C5: SignalType | D5: Direction | E5: EntryPrice | F5: ExitPrice | G5: PnL | H5: IsWin
A6: 6 | B6: Composite | C6: BUY | D6: LONG | E6: 1.10874 | F6: 1.10988 | G6: 114 | H6: =IF(G6>0,1,0) -> 1
A7: 11 | B7: MACD_Trend | C7: STRONG_BUY | D7: LONG | E7: 1.07416 | F7: 1.07588 | G7: 172 | H7: =IF(G7>0,1,0) -> 1
A8: 21 | B8: ML_XGB | C8: BUY | D8: LONG | E8: 1.10108 | F8: 1.10172 | G8: 64 | H8: =IF(G8>0,1,0) -> 1
A9: 30 | B9: Composite | C9: BUY | D9: LONG | E9: 1.08206 | F9: 1.08453 | G9: 247 | H9: =IF(G9>0,1,0) -> 1
A10: 31 | B10: MA_Cross | C10: STRONG_BUY | D10: LONG | E10: 1.09821 | F10: 1.09923 | G10: 102 | H10: =IF(G10>0,1,0) -> 1
A11: 32 | B11: MA_Cross | C11: SELL | D11: SHORT | E11: 1.06463 | F11: 1.0631 | G11: 153 | H11: =IF(G11>0,1,0) -> 1
A12: 34 | B12: RL_PPO | C12: BUY | D12: LONG | E12: 1.0643 | F12: 1.06311 | G12: -119 | H12: =IF(G12>0,1,0) -> 0
A13: 51 | B13: RL_PPO | C13: SELL | D13: SHORT | E13: 1.09359 | F13: 1.09554 | G13: -195 | H13: =IF(G13>0,1,0) -> 0
A14: 56 | B14: Composite | C14: STRONG_BUY | D14: LONG | E14: 1.07145 | F14: 1.0756 | G14: 415 | H14: =IF(G14>0,1,0) -> 1
A15: 70 | B15: MACD_Trend | C15: STRONG_BUY | D15: LONG | E15: 1.05697 | F15: 1.05848 | G15: 151 | H15: =IF(G15>0,1,0) -> 1
A16: 75 | B16: ML_RF | C16: STRONG_SELL | D16: SHORT | E16: 1.1023 | F16: 1.10125 | G16: 105 | H16: =IF(G16>0,1,0) -> 1
A17: 76 | B17: RSI_Reversal | C17: STRONG_SELL | D17: SHORT | E17: 1.0835 | F17: 1.08626 | G17: -276 | H17: =IF(G17>0,1,0) -> 0
... A38: 149 | B38: RSI_Reversal | C38: STRONG_SELL | D38: SHORT | E38: 1.06391 | F38: 1.06616 | G38: -225 | H38: =IF(G38>0,1,0) -> 0
A40: Total Trades | B40: =COUNT(A6:A38) -> 33
A41: Win Rate | B41: =SUM(H6:H38)/COUNT(A6:A38) -> 0.57575758
A42: Avg Trade PnL | B42: =AVERAGE(G6:G38) -> -2.2727273
A43: Gross Profit | B43: =SUMIF(G6:G38,">0") -> 3715
A44: Gross Loss | B44: =SUMIF(G6:G38,"<0") -> -3790
A45: Profit Factor | B45: =B43/ABS(B44) -> 0.98021108
A48: GBP/USD (32 trades)
A49: TradeID | B49: StrategyName | C49: SignalType | D49: Direction | E49: EntryPrice | F49: ExitPrice | G49: PnL | H49: IsWin
A50: 4 | B50: ML_RF | C50: SELL | D50: SHORT | E50: 1.23636 | F50: 1.23434 | G50: 202 | H50: =IF(G50>0,1,0) -> 1
A51: 9 | B51: RL_PPO | C51: BUY | D51: LONG | E51: 1.23686 | F51: 1.24044 | G51: 358 | H51: =IF(G51>0,1,0) -> 1
A52: 12 | B52: ML_XGB | C52: STRONG_SELL | D52: SHORT | E52: 1.28785 | F52: 1.28706 | G52: 79 | H52: =IF(G52>0,1,0) -> 1
A53: 15 | B53: Composite | C53: BUY | D53: LONG | E53: 1.22712 | F53: 1.22738 | G53: 26 | H53: =IF(G53>0,1,0) -> 1
A54: 24 | B54: Composite | C54: STRONG_BUY | D54: LONG | E54: 1.22121 | F54: 1.22688 | G54: 567 | H54: =IF(G54>0,1,0) -> 1
A55: 25 | B55: ML_XGB | C55: STRONG_SELL | D55: SHORT | E55: 1.27256 | F55: 1.27301 | G55: -45 | H55: =IF(G55>0,1,0) -> 0
A56: 26 | B56: ML_RF | C56: STRONG_SELL | D56: SHORT | E56: 1.22836 | F56: 1.22558 | G56: 278 | H56: =IF(G56>0,1,0) -> 1
A57: 27 | B57: ML_RF | C57: SELL | D57: SHORT | E57: 1.23718 | F57: 1.23653 | G57: 65 | H57: =IF(G57>0,1,0) -> 1
A58: 28 | B58: Composite | C58: STRONG_SELL | D58: SHORT | E58: 1.22826 | F58: 1.2301 | G58: -184 | H58: =IF(G58>0,1,0) -> 0
A59: 42 | B59: RL_PPO | C59: BUY | D59: LONG | E59: 1.24504 | F59: 1.24829 | G59: 325 | H59: =IF(G59>0,1,0) -> 1
A60: 49 | B60: ML_XGB | C60: BUY | D60: LONG | E60: 1.25202 | F60: 1.2501 | G60: -192 | H60: =IF(G60>0,1,0) -> 0
A61: 54 | B61: ML_RF | C61: BUY | D61: LONG | E61: 1.29586 | F61: 1.30103 | G61: 517 | H61: =IF(G61>0,1,0) -> 1
... A81: 148 | B81: MA_Cross | C81: STRONG_SELL | D81: SHORT | E81: 1.24366 | F81: 1.24291 | G81: 75 | H81: =IF(G81>0,1,0) -> 1
A83: Total Trades | B83: =COUNT(A50:A81) -> 32
A84: Win Rate | B84: =SUM(H50:H81)/COUNT(A50:A81) -> 0.71875
A85: Avg Trade PnL | B85: =AVERAGE(G50:G81) -> 140.96875
...
